## 超时或失败重试代码段

```js
async function retryWhenTimeOut ({
  func, timeout, times
}) {
  let i = 0
  while (times > i) {
    try {
      const res = await new Promise((resolve, reject) => {
        // 超时启动下一次循环重试
        const timer = setTimeout(() => {
          const message = `=== 执行函数${func.name}超时 ${++i} 次`
          // 在重试次数内, 抛出异常开始重试
          console.error(message)
          if (i < times) {
            reject(new Error('timeout'))
          }
        }, timeout)

        func().then(res => {
          resolve(res)
          clearTimeout(timer)
        }).catch(e => {
          // 失败启动下一次循环重试

          console.error(e)
          const message = `=== 执行函数${func.name}失败 ${++i} 次`
          console.error(message)
          reject(message)
          clearTimeout(timer)
        })
      })

      // 拿到结果, 直接返回结束循环
      return res
    } catch (error) {
      raven.error('=== retryWhenTimeOut ===')
      // 对于超时, 最终不会抛出异常, 最后一次失败的情况下, 抛出异常
      if (i >= times && error.message !== 'timeout') {
        throw error
      }
    }
  }
}

```

## promise 超时处理

```js
// 超时1s开始启动下一次请求, 任何一次请求成功返回, resolve promise, 中指请求.
// 其中一个promise 报错忽略, 所有的报错, reject promise
export async function retryWhenTimeOut ({
  func, timeout, times, funcName
}): Promise<any> {
  // eslint-disable-next-line promise/param-names
  return new Promise(async (resolve1, reject1) => {
    let i = 0
    let retryTimes = 0
    let failRetryTimes = 0

    const nextRetry = () => {
      return new Promise((resolve, reject) => {
        // 超时启动下一次循环重试
        const timer = setTimeout(async () => {
          if (i >= times) return
          ++i
          const message = `=== 执行函数${funcName}超时, 开始重试 ${++retryTimes} 次`
          // 在重试次数内, 抛出异常开始重试
          console.error(message)
          if (i < times) {
            nextRetry().then(resolve, reject)
          }
        }, timeout)

        const theTime = i + 1
        console.log('执行==', funcName)
        func().then(res => {
          console.log('=== retryWhenTimeOut === 返回结果', funcName, JSON.stringify(res))
          resolve(res)
          resolve1(res)
          clearTimeout(timer)
        }).catch(e => {
          // 失败启动下一次循环重试

          console.error(e)
          ++i
          ++failRetryTimes
          reject(e)
          clearTimeout(timer)
        })
      })
    }

    while (times > i) {
      try {
        const res = await nextRetry()
        // 拿到结果, 直接返回结束循环
        i = times
        return res
      } catch (error) {
        raven.error('=== retryWhenTimeOut ===')
        // 对于超时, 最终不会抛出异常, 最后一次失败的情况下, 抛出异常
        console.log(failRetryTimes)
        if (failRetryTimes > 5 && error?.message !== 'timeout') {
          i = times
          reject1(error)
          return
        }
        const message = `=== 执行函数${funcName}失败, 开始重试 ${retryTimes} 次`
        console.error(message)
      }
    }
  })
}

```
